Workbook

Sheet Cover
B2: Apple Inc.: Valuation Model
B3: 3-statement projection, DCF and hypothetical take-private LBO stress test
B5: Source filing | C5: 10-K, fiscal year ended 26 September 2015
B6: SEC CIK | C6: 320193
B7: Model generated | C7: 23 October 2026
B9: KEY OUTPUTS (linked)
B10: Current share price | C10: ='Inputs'!D7
B11: DCF implied share price: Gordon Growth | C11: ='DCF'!D49
B12: DCF implied share price: Exit Multiple | C12: ='DCF'!E49
B13: WACC | C13: ='DCF'!D21
B14: LBO entry EV / EBITDA | C14: ='LBO'!D8
B15: LBO implied offer price | C15: ='LBO'!D14
B16: Sponsor equity cheque | C16: ='LBO'!D39
B17: Sponsor MOIC | C17: ='LBO'!D100
B18: Sponsor IRR | C18: ='LBO'!D101
B19: Model integrity (all checks) | C19: =Checks!C4
B20: Investment committee recommendation | C20: PASS
B22: CONTENTS
B23: Inputs: market, operating and transaction assumptions (all hard-coded inputs live here)
B24: IS / BS / CFS: linked three-statement model, historical and projected
B25: Debt: existing debt tranches from the 10-K, reconciled to the balance sheet
B26: DCF: WACC, unlevered FCF, Gordon Growth and Exit Multiple valuation
B27: LBO: sources & uses, cash sweep waterfall, covenants, sponsor returns
B28: Checks: every accounting identity, with a master check
B30: CONVENTIONS
B31: Interest is calculated on beginning-of-year balances (no circular references).
B32: Funded debt is refinanced (held flat) in the standalone projection.
B33: Offshore cash is valued net of the repatriation tax implied by the 10-K.
B34: Apple is far beyond any realised LBO size; the LBO is a hypothetical stress test.

Sheet Inputs
B1: Apple Inc.: Assumptions & Inputs
B2: USD in millions, except per-share data. Blue = input / reported, black = formula, green = link to another sheet.
D3: Historical (actual ratios) | G3: Projection drivers
B4: Fiscal year ending September | D4: 2013 | E4: 2014 | F4: 2015 | G4: 2016 | H4: 2017 | I4: 2018 | J4: 2019 | K4: 2020
B6: Market & valuation inputs
B7: Current share price | D7: 114.71
B8: Risk-free rate (10Y Treasury) | D8: 0.0213
B9: Equity risk premium | D9: 0.06
B10: Levered beta | D10: 1
B11: Marginal tax rate (WACC tax shield) | D11: 0.264
B12: Terminal growth rate (Gordon) | D12: 0.025
B13: Terminal EV / EBITDA multiple | D13: 10
B14: Mid-year discounting (1 = on) | D14: 1
B15: Deduct repatriation tax in equity bridge (1 = on) | D15: 1
B16: Repatriation tax rate | D16: =D26/D25
B17: Days in year | D17: 365
B19: Filing disclosures (10-K, latest fiscal year end)
B20: Shares outstanding at year end | C20: m | D20: 5578.753
B21: Weighted-average basic shares | C21: m | D21: 5753.421
B22: Weighted-average diluted shares | C22: m | D22: 5793.069
B23: Diluted shares (period-end + dilution) | C23: m | D23: =D20+D22-D21
B24: Cash & securities held by foreign subsidiaries | D24: 186900
B25: Undistributed foreign earnings | D25: 91500
B26: Unrecognized deferred tax on foreign earnings | D26: 30000
B27: Yield on cash & marketable securities | D27: 0.0149
B29: Operating drivers
B30: Revenue growth | E30: ='IS'!E7/'IS'!D7-1 | F30: ='IS'!F7/'IS'!E7-1 | G30: 0.03 | H30: 0.04 | I30: 0.04 | J30: 0.035 | K30: 0.03
B31: Gross margin | D31: ='IS'!D9/'IS'!D7 | E31: ='IS'!E9/'IS'!E7 | F31: ='IS'!F9/'IS'!F7 | G31: 0.4 | H31: 0.4 | I31: 0.395 | J31: 0.395 | K31: 0.39
B32: R&D, % of sales | D32: ='IS'!D11/'IS'!D7 | E32: ='IS'!E11/'IS'!E7 | F32: ='IS'!F11/'IS'!F7 | G32: 0.037 | H32: 0.038 | I32: 0.039 | J32: 0.04 | K32: 0.04
B33: SG&A, % of sales | D33: ='IS'!D12/'IS'!D7 | E33: ='IS'!E12/'IS'!E7 | F33: ='IS'!F12/'IS'!F7 | G33: 0.062 | H33: 0.062 | I33: 0.062 | J33: 0.062 | K33: 0.062
B34: D&A, % of sales | D34: ='IS'!D16/'IS'!D7 | E34: ='IS'!E16/'IS'!E7 | F34: ='IS'!F16/'IS'!F7 | G34: 0.048 | H34: 0.048 | I34: 0.048 | J34: 0.048 | K34: 0.048
B35: Capex, % of sales | D35: =-'CFS'!D28/'IS'!D7 | E35: =-'CFS'!E28/'IS'!E7 | F35: =-'CFS'!F28/'IS'!F7 | G35: 0.06 | H35: 0.055 | I35: 0.05 | J35: 0.05 | K35: 0.05
B36: Tax rate | D36: ='IS'!D23/'IS'!D22 | E36: ='IS'!E23/'IS'!E22 | F36: ='IS'!F23/'IS'!F22 | G36: 0.264 | H36: 0.264 | I36: 0.264 | J36: 0.264 | K36: 0.264
B37: Receivable days | E37: ='BS'!E9/'IS'!E7*$D$17 | F37: ='BS'!F9/'IS'!F7*$D$17 | G37: =$F$37 | H37: =$F$37 | I37: =$F$37 | J37: =$F$37 | K37: =$F$37
B38: Inventory days | E38: ='BS'!E10/'IS'!E8*$D$17 | F38: ='BS'!F10/'IS'!F8*$D$17 | G38: =$F$38 | H38: =$F$38 | I38: =$F$38 | J38: =$F$38 | K38: =$F$38
B39: Payable days | E39: ='BS'!E23/'IS'!E8*$D$17 | F39: ='BS'!F23/'IS'!F8*$D$17 | G39: =$F$39 | H39: =$F$39 | I39: =$F$39 | J39: =$F$39 | K39: =$F$39
B40: Vendor receivables % sales | E40: ='BS'!E12/'IS'!E7 | F40: ='BS'!F12/'IS'!F7 | G40: =$F$40 | H40: =$F$40 | I40: =$F$40 | J40: =$F$40 | K40: =$F$40
B41: Other current assets % sales | E41: ='BS'!E13/'IS'!E7 | F41: ='BS'!F13/'IS'!F7 | G41: =$F$41 | H41: =$F$41 | I41: =$F$41 | J41: =$F$41 | K41: =$F$41
B42: Accrued expenses % sales | E42: ='BS'!E24/'IS'!E7 | F42: ='BS'!F24/'IS'!F7 | G42: =$F$42 | H42: =$F$42 | I42: =$F$42 | J42: =$F$42 | K42: =$F$42
B43: Deferred revenue % sales | E43: ='BS'!E25/'IS'!E7 | F43: ='BS'!F25/'IS'!F7 | G43: =$F$43 | H43: =$F$43 | I43: =$F$43 | J43: =$F$43 | K43: =$F$43
...

Sheet IS
B1: Apple Inc.: Income Statement
B2: USD in millions, except per-share data. Blue = input / reported, black = formula, green = link to another sheet.
D3: Historical | G3: Projected
B4: Fiscal year ending September | D4: 2013 | E4: 2014 | F4: 2015 | G4: 2016 | H4: 2017 | I4: 2018 | J4: 2019 | K4: 2020
B6: Income statement
B7: Net sales | D7: 170910 | E7: 182795 | F7: 233715 | G7: =F7*(1+'Inputs'!G30) | H7: =G7*(1+'Inputs'!H30) | I7: =H7*(1+'Inputs'!I30) | J7: =I7*(1+'Inputs'!J30) | K7: =J7*(1+'Inputs'!K30)
B8: Cost of sales | D8: 106606 | E8: 112258 | F8: 140089 | G8: =G7*(1-'Inputs'!G31) | H8: =H7*(1-'Inputs'!H31) | I8: =I7*(1-'Inputs'!I31) | J8: =J7*(1-'Inputs'!J31) | K8: =K7*(1-'Inputs'!K31)
B9: Gross profit | D9: =D7-D8 | E9: =E7-E8 | F9: =F7-F8 | G9: =G7-G8 | H9: =H7-H8 | I9: =I7-I8 | J9: =J7-J8 | K9: =K7-K8
B10: Gross margin % | D10: =D9/D7 | E10: =E9/E7 | F10: =F9/F7 | G10: =G9/G7 | H10: =H9/H7 | I10: =I9/I7 | J10: =J9/J7 | K10: =K9/K7
B11: Research and development | D11: 4475 | E11: 6041 | F11: 8067 | G11: =G7*'Inputs'!G32 | H11: =H7*'Inputs'!H32 | I11: =I7*'Inputs'!I32 | J11: =J7*'Inputs'!J32 | K11: =K7*'Inputs'!K32
B12: Selling, general and administrative | D12: 10830 | E12: 11993 | F12: 14329 | G12: =G7*'Inputs'!G33 | H12: =H7*'Inputs'!H33 | I12: =I7*'Inputs'!I33 | J12: =J7*'Inputs'!J33 | K12: =K7*'Inputs'!K33
B13: Total operating expenses | D13: =SUM(D11:D12) | E13: =SUM(E11:E12) | F13: =SUM(F11:F12) | G13: =SUM(G11:G12) | H13: =SUM(H11:H12) | I13: =SUM(I11:I12) | J13: =SUM(J11:J12) | K13: =SUM(K11:K12)
B14: Operating income (EBIT) | D14: =D9-D13 | E14: =E9-E13 | F14: =F9-F13 | G14: =G9-G13 | H14: =H9-H13 | I14: =I9-I13 | J14: =J9-J13 | K14: =K9-K13
B15: EBIT margin % | D15: =D14/D7 | E15: =E14/E7 | F15: =F14/F7 | G15: =G14/G7 | H15: =H14/H7 | I15: =I14/I7 | J15: =J14/J7 | K15: =K14/K7
B16: Depreciation & amortization | D16: ='CFS'!D10 | E16: ='CFS'!E10 | F16: ='CFS'!F10 | G16: =G7*'Inputs'!G34 | H16: =H7*'Inputs'!H34 | I16: =I7*'Inputs'!I34 | J16: =J7*'Inputs'!J34 | K16: =K7*'Inputs'!K34
B17: EBITDA | D17: =D14+D16 | E17: =E14+E16 | F17: =F14+F16 | G17: =G14+G16 | H17: =H14+H16 | I17: =I14+I16 | J17: =J14+J16 | K17: =K14+K16
B18: EBITDA margin % | D18: =D17/D7 | E18: =E17/E7 | F18: =F17/F7 | G18: =G17/G7 | H18: =H17/H7 | I18: =I17/I7 | J18: =J17/J7 | K18: =K17/K7
B19: Interest income | G19: ='Inputs'!G44*('BS'!F7+'BS'!F8+'BS'!F15) | H19: ='Inputs'!H44*('BS'!G7+'BS'!G8+'BS'!G15) | I19: ='Inputs'!I44*('BS'!H7+'BS'!H8+'BS'!H15) | J19: ='Inputs'!J44*('BS'!I7+'BS'!I8+'BS'!I15) | K19: ='Inputs'!K44*('BS'!J7+'BS'!J8+'BS'!J15)
B20: Interest expense | G20: ='Inputs'!G45*('BS'!F26+'BS'!F27+'BS'!F30) | H20: ='Inputs'!H45*('BS'!G26+'BS'!G27+'BS'!G30) | I20: ='Inputs'!I45*('BS'!H26+'BS'!H27+'BS'!H30) | J20: ='Inputs'!J45*('BS'!I26+'BS'!I27+'BS'!I30) | K20: ='Inputs'!K45*('BS'!J26+'BS'!J27+'BS'!J30)
B21: Other income / (expense), net | D21: 1156 | E21: 980 | F21: 1285 | G21: =G19-G20 | H21: =H19-H20 | I21: =I19-I20 | J21: =J19-J20 | K21: =K19-K20
B22: Income before taxes | D22: =D14+D21 | E22: =E14+E21 | F22: =F14+F21 | G22: =G14+G21 | H22: =H14+H21 | I22: =I14+I21 | J22: =J14+J21 | K22: =K14+K21
B23: Provision for income taxes | D23: 13118 | E23: 13973 | F23: 19121 | G23: =G22*'Inputs'!G36 | H23: =H22*'Inputs'!H36 | I23: =I22*'Inputs'!I36 | J23: =J22*'Inputs'!J36 | K23: =K22*'Inputs'!K36
B24: Net income | D24: =D22-D23 | E24: =E22-E23 | F24: =F22-F23 | G24: =G22-G23 | H24: =H22-H23 | I24: =I22-I23 | J24: =J22-J23 | K24: =K22-K23
B26: Diluted shares | C26: m | D26: 6521.634 | E26: 6122.663 | F26: 5793.069 | G26: ='Inputs'!$D$23 | H26: ='Inputs'!$D$23 | I26: ='Inputs'!$D$23 | J26: ='Inputs'!$D$23 | K26: ='Inputs'!$D$23
B27: Diluted EPS | D27: =D24/D26 | E27: =E24/E26 | F27: =F24/F26 | G27: =G24/G26 | H27: =H24/H26 | I27: =I24/I26 | J27: =J24/J26 | K27: =K24/K26
B29: Net sales by segment (reported)
B30: Americas | D30: 77093 | E30: 80095 | F30: 93864
B31: Europe | D31: 40980 | E31: 44285 | F31: 50337
B32: Greater China | D32: 27016 | E32: 31853 | F32: 58715
B33: Japan | D33: 13782 | E33: 15314 | F33: 15706
B34: Rest of Asia Pacific | D34: 12039 | E34: 11248 | F34: 15093
B35: Total | D35: =SUM(D30:D34) | E35: =SUM(E30:E34) | F35: =SUM(F30:F34)
B36: Check: segments - net sales | D36: =D35-D7 | E36: =E35-E7 | F36: =F35-F7
B38: Net sales by product (reported)
B39: iPhone | D39: 91279 | E39: 101991 | F39: 155041
B40: iPad | D40: 31980 | E40: 30283 | F40: 23227
B41: Mac | D41: 21483 | E41: 24079 | F41: 25471
B42: Services | D42: 16051 | E42: 18063 | F42: 19909
B43: Other Products | D43: 10117 | E43: 8379 | F43: 10067
B44: Total | D44: =SUM(D39:D43) | E44: =SUM(E39:E43) | F44: =SUM(F39:F43)
...

Sheet BS
B1: Apple Inc.: Balance Sheet
B2: USD in millions, except per-share data. Blue = input / reported, black = formula, green = link to another sheet.
E3: Historical | G3: Projected
B4: Fiscal year ending September | E4: 2014 | F4: 2015 | G4: 2016 | H4: 2017 | I4: 2018 | J4: 2019 | K4: 2020
B6: Assets
B7: Cash and cash equivalents | E7: 13844 | F7: 21120 | G7: ='CFS'!G46 | H7: ='CFS'!H46 | I7: ='CFS'!I46 | J7: ='CFS'!J46 | K7: ='CFS'!K46
B8: Short-term marketable securities | E8: 11233 | F8: 20481 | G8: =F8 | H8: =G8 | I8: =H8 | J8: =I8 | K8: =J8
B9: Accounts receivable | E9: 17460 | F9: 16849 | G9: ='IS'!G7*'Inputs'!G37/'Inputs'!$D$17 | H9: ='IS'!H7*'Inputs'!H37/'Inputs'!$D$17 | I9: ='IS'!I7*'Inputs'!I37/'Inputs'!$D$17 | J9: ='IS'!J7*'Inputs'!J37/'Inputs'!$D$17 | K9: ='IS'!K7*'Inputs'!K37/'Inputs'!$D$17
B10: Inventories | E10: 2111 | F10: 2349 | G10: ='IS'!G8*'Inputs'!G38/'Inputs'!$D$17 | H10: ='IS'!H8*'Inputs'!H38/'Inputs'!$D$17 | I10: ='IS'!I8*'Inputs'!I38/'Inputs'!$D$17 | J10: ='IS'!J8*'Inputs'!J38/'Inputs'!$D$17 | K10: ='IS'!K8*'Inputs'!K38/'Inputs'!$D$17
B11: Deferred tax assets | E11: 4318 | F11: 5546 | G11: =F11 | H11: =G11 | I11: =H11 | J11: =I11 | K11: =J11
B12: Vendor non-trade receivables | E12: 9759 | F12: 13494 | G12: ='IS'!G7*'Inputs'!G40 | H12: ='IS'!H7*'Inputs'!H40 | I12: ='IS'!I7*'Inputs'!I40 | J12: ='IS'!J7*'Inputs'!J40 | K12: ='IS'!K7*'Inputs'!K40
B13: Other current assets | E13: 9806 | F13: 9539 | G13: ='IS'!G7*'Inputs'!G41 | H13: ='IS'!H7*'Inputs'!H41 | I13: ='IS'!I7*'Inputs'!I41 | J13: ='IS'!J7*'Inputs'!J41 | K13: ='IS'!K7*'Inputs'!K41
B14: Total current assets | E14: =SUM(E7:E13) | F14: =SUM(F7:F13) | G14: =SUM(G7:G13) | H14: =SUM(H7:H13) | I14: =SUM(I7:I13) | J14: =SUM(J7:J13) | K14: =SUM(K7:K13)
B15: Long-term marketable securities | E15: 130162 | F15: 164065 | G15: =F15 | H15: =G15 | I15: =H15 | J15: =I15 | K15: =J15
B16: Property, plant and equipment, net | E16: 20624 | F16: 22471 | G16: =F16-'CFS'!G28-'IS'!G16 | H16: =G16-'CFS'!H28-'IS'!H16 | I16: =H16-'CFS'!I28-'IS'!I16 | J16: =I16-'CFS'!J28-'IS'!J16 | K16: =J16-'CFS'!K28-'IS'!K16
B17: Goodwill | E17: 4616 | F17: 5116 | G17: =F17 | H17: =G17 | I17: =H17 | J17: =I17 | K17: =J17
B18: Acquired intangible assets, net | E18: 4142 | F18: 3893 | G18: =F18 | H18: =G18 | I18: =H18 | J18: =I18 | K18: =J18
B19: Other assets | E19: 3764 | F19: 5556 | G19: =F19 | H19: =G19 | I19: =H19 | J19: =I19 | K19: =J19
B20: Total assets | E20: =E14+SUM(E15:E19) | F20: =F14+SUM(F15:F19) | G20: =G14+SUM(G15:G19) | H20: =H14+SUM(H15:H19) | I20: =I14+SUM(I15:I19) | J20: =J14+SUM(J15:J19) | K20: =K14+SUM(K15:K19)
B22: Liabilities
B23: Accounts payable | E23: 30196 | F23: 35490 | G23: ='IS'!G8*'Inputs'!G39/'Inputs'!$D$17 | H23: ='IS'!H8*'Inputs'!H39/'Inputs'!$D$17 | I23: ='IS'!I8*'Inputs'!I39/'Inputs'!$D$17 | J23: ='IS'!J8*'Inputs'!J39/'Inputs'!$D$17 | K23: ='IS'!K8*'Inputs'!K39/'Inputs'!$D$17
B24: Accrued expenses | E24: 18453 | F24: 25181 | G24: ='IS'!G7*'Inputs'!G42 | H24: ='IS'!H7*'Inputs'!H42 | I24: ='IS'!I7*'Inputs'!I42 | J24: ='IS'!J7*'Inputs'!J42 | K24: ='IS'!K7*'Inputs'!K42
B25: Deferred revenue | E25: 8491 | F25: 8940 | G25: ='IS'!G7*'Inputs'!G43 | H25: ='IS'!H7*'Inputs'!H43 | I25: ='IS'!I7*'Inputs'!I43 | J25: ='IS'!J7*'Inputs'!J43 | K25: ='IS'!K7*'Inputs'!K43
B26: Commercial paper | E26: 6308 | F26: 8499 | G26: =F26 | H26: =G26 | I26: =H26 | J26: =I26 | K26: =J26
B27: Current portion of long-term debt | E27: 0 | F27: 2500 | G27: =F27 | H27: =G27 | I27: =H27 | J27: =I27 | K27: =J27
B28: Total current liabilities | E28: =SUM(E23:E27) | F28: =SUM(F23:F27) | G28: =SUM(G23:G27) | H28: =SUM(H23:H27) | I28: =SUM(I23:I27) | J28: =SUM(J23:J27) | K28: =SUM(K23:K27)
B29: Deferred revenue, non-current | E29: 3031 | F29: 3624 | G29: =F29 | H29: =G29 | I29: =H29 | J29: =I29 | K29: =J29
B30: Long-term debt | E30: 28987 | F30: 53463 | G30: =F30 | H30: =G30 | I30: =H30 | J30: =I30 | K30: =J30
B31: Other non-current liabilities | E31: 24826 | F31: 33427 | G31: =F31 | H31: =G31 | I31: =H31 | J31: =I31 | K31: =J31
B32: Total liabilities | E32: =E28+SUM(E29:E31) | F32: =F28+SUM(F29:F31) | G32: =G28+SUM(G29:G31) | H32: =H28+SUM(H29:H31) | I32: =I28+SUM(I29:I31) | J32: =J28+SUM(J29:J31) | K32: =K28+SUM(K29:K31)
B34: Shareholders' equity
B35: Common stock and additional paid-in capital | E35: 23313 | F35: 27416 | G35: =F35 | H35: =G35 | I35: =H35 | J35: =I35 | K35: =J35
B36: Retained earnings | E36: 87152 | F36: 92284 | G36: =F36+'IS'!G24+'CFS'!G37+'CFS'!G38 | H36: =G36+'IS'!H24+'CFS'!H37+'CFS'!H38 | I36: =H36+'IS'!I24+'CFS'!I37+'CFS'!I38 | J36: =I36+'IS'!J24+'CFS'!J37+'CFS'!J38 | K36: =J36+'IS'!K24+'CFS'!K37+'CFS'!K38
B37: Accumulated other comprehensive income | E37: 1082 | F37: -345 | G37: =F37 | H37: =G37 | I37: =H37 | J37: =I37 | K37: =J37
B38: Total shareholders' equity | E38: =SUM(E35:E37) | F38: =SUM(F35:F37) | G38: =SUM(G35:G37) | H38: =SUM(H35:H37) | I38: =SUM(I35:I37) | J38: =SUM(J35:J37) | K38: =SUM(K35:K37)
B39: Total liabilities and shareholders' equity | E39: =E32+E38 | F39: =F32+F38 | G39: =G32+G38 | H39: =H32+H38 | I39: =I32+I38 | J39: =J32+J38 | K39: =K32+K38
B40: Check: Assets - (Liabilities + Equity) | E40: =E20-E39 | F40: =F20-F39 | G40: =G20-G39 | H40: =H20-H39 | I40: =I20-I39 | J40: =J20-J39 | K40: =K20-K39
B42: Memo
B43: Net working capital (operating) | E43: =(E14-E7-E8-E11)-(E28-E26-E27) | F43: =(F14-F7-F8-F11)-(F28-F26-F27) | G43: =(G14-G7-G8-G11)-(G28-G26-G27) | H43: =(H14-H7-H8-H11)-(H28-H26-H27) | I43: =(I14-I7-I8-I11)-(I28-I26-I27) | J43: =(J14-J7-J8-J11)-(J28-J26-J27) | K43: =(K14-K7-K8-K11)-(K28-K26-K27)
B44: Total debt | E44: =E26+E27+E30 | F44: =F26+F27+F30 | G44: =G26+G27+G30 | H44: =H26+H27+H30 | I44: =I26+I27+I30 | J44: =J26+J27+J30 | K44: =K26+K27+K30
...

Sheet CFS
B1: Apple Inc.: Cash Flow Statement
B2: USD in millions, except per-share data. Blue = input / reported, black = formula, green = link to another sheet.
D3: Historical | G3: Projected
B4: Fiscal year ending September | D4: 2013 | E4: 2014 | F4: 2015 | G4: 2016 | H4: 2017 | I4: 2018 | J4: 2019 | K4: 2020
B6: Cash, beginning of year | D6: 10746 | E6: 14259 | F6: 13844 | G6: ='BS'!F7 | H6: ='BS'!G7 | I6: ='BS'!H7 | J6: ='BS'!I7 | K6: ='BS'!J7
B8: Operating activities
B9: Net income | D9: 37037 | E9: 39510 | F9: 53394 | G9: ='IS'!G24 | H9: ='IS'!H24 | I9: ='IS'!I24 | J9: ='IS'!J24 | K9: ='IS'!K24
B10: Depreciation and amortization | D10: 6757 | E10: 7946 | F10: 11257 | G10: ='IS'!G16 | H10: ='IS'!H16 | I10: ='IS'!I16 | J10: ='IS'!J16 | K10: ='IS'!K16
B11: Share-based compensation | D11: 2253 | E11: 2863 | F11: 3586
B12: Deferred income taxes | D12: 1141 | E12: 2347 | F12: 1382
B13: Other non-cash items | D13: 0 | E13: 0 | F13: 0
B14: (Increase) / decrease in receivables | D14: -2172 | E14: -4232 | F14: 611 | G14: ='BS'!F9-'BS'!G9 | H14: ='BS'!G9-'BS'!H9 | I14: ='BS'!H9-'BS'!I9 | J14: ='BS'!I9-'BS'!J9 | K14: ='BS'!J9-'BS'!K9
B15: (Increase) / decrease in inventories | D15: -973 | E15: -76 | F15: -238 | G15: ='BS'!F10-'BS'!G10 | H15: ='BS'!G10-'BS'!H10 | I15: ='BS'!H10-'BS'!I10 | J15: ='BS'!I10-'BS'!J10 | K15: ='BS'!J10-'BS'!K10
B16: (Increase) / decrease in vendor receivables | D16: 223 | E16: -2220 | F16: -3735 | G16: ='BS'!F12-'BS'!G12 | H16: ='BS'!G12-'BS'!H12 | I16: ='BS'!H12-'BS'!I12 | J16: ='BS'!I12-'BS'!J12 | K16: ='BS'!J12-'BS'!K12
B17: (Increase) / decrease in other assets | D17: 1080 | E17: 167 | F17: -179 | G17: ='BS'!F13-'BS'!G13 | H17: ='BS'!G13-'BS'!H13 | I17: ='BS'!H13-'BS'!I13 | J17: ='BS'!I13-'BS'!J13 | K17: ='BS'!J13-'BS'!K13
B18: Increase / (decrease) in payables | D18: 2340 | E18: 5938 | F18: 5400 | G18: ='BS'!G23-'BS'!F23 | H18: ='BS'!H23-'BS'!G23 | I18: ='BS'!I23-'BS'!H23 | J18: ='BS'!J23-'BS'!I23 | K18: ='BS'!K23-'BS'!J23
B19: Increase / (decrease) in deferred revenue | D19: 1459 | E19: 1460 | F19: 1042 | G19: ='BS'!G25-'BS'!F25 | H19: ='BS'!H25-'BS'!G25 | I19: ='BS'!I25-'BS'!H25 | J19: ='BS'!J25-'BS'!I25 | K19: ='BS'!K25-'BS'!J25
B20: Increase / (decrease) in other liabilities | D20: 4521 | E20: 6010 | F20: 8746 | G20: ='BS'!G24-'BS'!F24 | H20: ='BS'!H24-'BS'!G24 | I20: ='BS'!I24-'BS'!H24 | J20: ='BS'!J24-'BS'!I24 | K20: ='BS'!K24-'BS'!J24
B21: Cash from operating activities | D21: =SUM(D9:D20) | E21: =SUM(E9:E20) | F21: =SUM(F9:F20) | G21: =SUM(G9:G20) | H21: =SUM(H9:H20) | I21: =SUM(I9:I20) | J21: =SUM(J9:J20) | K21: =SUM(K9:K20)
B23: Investing activities
B24: Purchases of marketable securities | D24: -148489 | E24: -217128 | F24: -166402
B25: Maturities of marketable securities | D25: 20317 | E25: 18810 | F25: 14538
B26: Sales of marketable securities | D26: 104130 | E26: 189301 | F26: 107447
B27: Business acquisitions, net | D27: -496 | E27: -3765 | F27: -343
B28: Capital expenditures | D28: -8165 | E28: -9571 | F28: -11247 | G28: =-'IS'!G7*'Inputs'!G35 | H28: =-'IS'!H7*'Inputs'!H35 | I28: =-'IS'!I7*'Inputs'!I35 | J28: =-'IS'!J7*'Inputs'!J35 | K28: =-'IS'!K7*'Inputs'!K35
B29: Purchases of intangible assets | D29: -911 | E29: -242 | F29: -241
B30: Other investing | D30: -160 | E30: 16 | F30: -26
B31: Cash from investing activities | D31: =SUM(D24:D30) | E31: =SUM(E24:E30) | F31: =SUM(F24:F30) | G31: =SUM(G24:G30) | H31: =SUM(H24:H30) | I31: =SUM(I24:I30) | J31: =SUM(J24:J30) | K31: =SUM(K24:K30)
B33: Financing activities
B34: Proceeds from issuance of common stock | D34: 530 | E34: 730 | F34: 543
B35: Excess tax benefits from equity awards | D35: 701 | E35: 739 | F35: 749
B36: Taxes on net share settlement | D36: -1082 | E36: -1158 | F36: -1499
B37: Dividends paid | D37: -10564 | E37: -11126 | F37: -11561 | G37: =-'IS'!G24*'Inputs'!G46 | H37: =-'IS'!H24*'Inputs'!H46 | I37: =-'IS'!I24*'Inputs'!I46 | J37: =-'IS'!J24*'Inputs'!J46 | K37: =-'IS'!K24*'Inputs'!K46
B38: Repurchases of common stock | D38: -22860 | E38: -45000 | F38: -35253 | G38: =-'IS'!G24*'Inputs'!G47 | H38: =-'IS'!H24*'Inputs'!H47 | I38: =-'IS'!I24*'Inputs'!I47 | J38: =-'IS'!J24*'Inputs'!J47 | K38: =-'IS'!K24*'Inputs'!K47
B39: Proceeds from issuance of debt, net | D39: 16896 | E39: 11960 | F39: 27114
B40: Repayment of debt | D40: 0 | E40: 0 | F40: 0
B41: Change in commercial paper, net | D41: 0 | E41: 6306 | F41: 2191
B42: Other financing | D42: 0 | E42: 0 | F42: 0
B43: Cash from financing activities | D43: =SUM(D34:D42) | E43: =SUM(E34:E42) | F43: =SUM(F34:F42) | G43: =SUM(G34:G42) | H43: =SUM(H34:H42) | I43: =SUM(I34:I42) | J43: =SUM(J34:J42) | K43: =SUM(K34:K42)
B45: Net change in cash | D45: =D21+D31+D43 | E45: =E21+E31+E43 | F45: =F21+F31+F43 | G45: =G21+G31+G43 | H45: =H21+H31+H43 | I45: =I21+I31+I43 | J45: =J21+J31+J43 | K45: =K21+K31+K43
...

Sheet Debt
B1: Apple Inc.: Existing Debt Schedule (10-K)
B2: USD in millions, except per-share data. Blue = input / reported, black = formula, green = link to another sheet.
B6: Term debt tranches | C6: Currency | D6: Principal | E6: Eff. rate low | F6: Eff. rate high | G6: Eff. rate mid | H6: Maturity from | I6: Maturity to
B7: Floating-rate notes due 2016-2018 (USD) | C7: USD | D7: 3000 | E7: 0.0051 | F7: 0.011 | G7: =(E7+F7)/2 | H7: 2016 | I7: 2018
B8: Fixed-rate 0.45%-3.85% notes due 2016-2043 (USD) | C8: USD | D8: 14000 | E8: 0.0051 | F8: 0.0391 | G8: =(E8+F8)/2 | H8: 2016 | I8: 2043
B9: Floating-rate notes due 2017-2019 (USD) | C9: USD | D9: 2000 | E9: 0.0037 | F9: 0.006 | G9: =(E9+F9)/2 | H9: 2017 | I9: 2019
B10: Fixed-rate 1.05%-4.45% notes due 2017-2044 (USD) | C10: USD | D10: 10000 | E10: 0.0037 | F10: 0.0448 | G10: =(E10+F10)/2 | H10: 2017 | I10: 2044
B11: Fixed-rate 1.000% notes due 2022 (EUR) | C11: EUR | D11: 1558 | E11: 0.0294 | F11: 0.0294 | G11: =(E11+F11)/2 | H11: 2022 | I11: 2022
B12: Fixed-rate 1.625% notes due 2026 (EUR) | C12: EUR | D12: 1558 | E12: 0.0345 | F12: 0.0345 | G12: =(E12+F12)/2 | H12: 2026 | I12: 2026
B13: Floating-rate notes due 2020 (USD) | C13: USD | D13: 500 | E13: 0.0056 | F13: 0.0056 | G13: =(E13+F13)/2 | H13: 2020 | I13: 2020
B14: Fixed-rate 1.55% notes due 2020 (USD) | C14: USD | D14: 1250 | E14: 0.0056 | F14: 0.0056 | G14: =(E14+F14)/2 | H14: 2020 | I14: 2020
B15: Fixed-rate 2.15% notes due 2022 (USD) | C15: USD | D15: 1250 | E15: 0.0087 | F15: 0.0087 | G15: =(E15+F15)/2 | H15: 2022 | I15: 2022
B16: Fixed-rate 2.50% notes due 2025 (USD) | C16: USD | D16: 1500 | E16: 0.026 | F16: 0.026 | G16: =(E16+F16)/2 | H16: 2025 | I16: 2025
B17: Fixed-rate 3.45% notes due 2045 (USD) | C17: USD | D17: 2000 | E17: 0.0358 | F17: 0.0358 | G17: =(E17+F17)/2 | H17: 2045 | I17: 2045
B18: Fixed-rate 0.375% notes due 2024 (CHF) | C18: CHF | D18: 895 | E18: 0.0028 | F18: 0.0028 | G18: =(E18+F18)/2 | H18: 2024 | I18: 2024
... B34: Fixed-rate 2.000% notes due 2027 (EUR) | C34: EUR | D34: 1113 | E34: 0.0385 | F34: 0.0385 | G34: =(E34+F34)/2 | H34: 2027 | I34: 2027
B36: Reconciliation to balance sheet
B37: Sum of tranche principal | D37: =SUM(D7:D34)
B38: Total term debt (reported) | D38: 55701
B39: Check: tranches - reported total | D39: =D37-D38
B40: Unamortized discount | D40: -114
B41: Hedge accounting fair value adjustments | D41: 376
B42: Carrying value of term debt | D42: =D38+D40+D41
B43: Balance sheet: current + long-term debt | D43: ='BS'!F27+'BS'!F30
B44: Check: carrying value - balance sheet | D44: =D42-D43
B45: Commercial paper outstanding | D45: ='BS'!F26
B46: Commercial paper weighted-average rate | D46: 0.0014
B47: Term debt weighted-average effective rate | D47: =SUMPRODUCT(D7:D34,G7:G34)/D37
B48: Blended pre-tax cost of debt | D48: =(SUMPRODUCT(D7:D34,G7:G34)+D45*D46)/(D37+D45)

Sheet DCF
B1: Apple Inc.: Discounted Cash Flow Valuation
B2: USD in millions, except per-share data. Blue = input / reported, black = formula, green = link to another sheet.
F3: Actual | G3: Projected
B4: Fiscal year ending September | F4: 2015 | G4: 2016 | H4: 2017 | I4: 2018 | J4: 2019 | K4: 2020
B6: Weighted average cost of capital
B7: Share price | D7: ='Inputs'!$D$7
B8: Diluted shares (m) | D8: ='Inputs'!$D$23
B9: Market value of equity | D9: =$D$7*$D$8
B10: Total debt (book) | D10: ='BS'!F44
B11: Total capitalization | D11: =$D$9+$D$10
B12: Equity / total capitalization | D12: =$D$9/$D$11
B13: Debt / total capitalization | D13: =$D$10/$D$11
B14: Risk-free rate | D14: ='Inputs'!$D$8
B15: Levered beta | D15: ='Inputs'!$D$10
B16: Equity risk premium | D16: ='Inputs'!$D$9
B17: Cost of equity (CAPM) | D17: =$D$14+$D$15*$D$16
B18: Pre-tax cost of debt | D18: ='Inputs'!$G$45
B19: Marginal tax rate | D19: ='Inputs'!$D$11
B20: After-tax cost of debt | D20: =$D$18*(1-$D$19)
B21: WACC | D21: =$D$12*$D$17+$D$13*$D$20
B23: Unlevered free cash flow
B24: EBIT | G24: ='IS'!G14 | H24: ='IS'!H14 | I24: ='IS'!I14 | J24: ='IS'!J14 | K24: ='IS'!K14
B25: Tax rate | G25: ='Inputs'!G36 | H25: ='Inputs'!H36 | I25: ='Inputs'!I36 | J25: ='Inputs'!J36 | K25: ='Inputs'!K36
B26: NOPAT = EBIT x (1 - t) | G26: =G24*(1-G25) | H26: =H24*(1-H25) | I26: =I24*(1-I25) | J26: =J24*(1-J25) | K26: =K24*(1-K25)
B27: Plus: D&A | G27: ='IS'!G16 | H27: ='IS'!H16 | I27: ='IS'!I16 | J27: ='IS'!J16 | K27: ='IS'!K16
B28: Less: capital expenditures | G28: =-'CFS'!G28 | H28: =-'CFS'!H28 | I28: =-'CFS'!I28 | J28: =-'CFS'!J28 | K28: =-'CFS'!K28
B29: Less: increase in net working capital | G29: ='BS'!G43-'BS'!F43 | H29: ='BS'!H43-'BS'!G43 | I29: ='BS'!I43-'BS'!H43 | J29: ='BS'!J43-'BS'!I43 | K29: ='BS'!K43-'BS'!J43
B30: Unlevered free cash flow | G30: =G26+G27-G28-G29 | H30: =H26+H27-H28-H29 | I30: =I26+I27-I28-I29 | J30: =J26+J27-J28-J29 | K30: =K26+K27-K28-K29
B31: Year | G31: =G$4-$F$4 | H31: =H$4-$F$4 | I31: =I$4-$F$4 | J31: =J$4-$F$4 | K31: =K$4-$F$4
B32: Discount period | G32: =IF('Inputs'!$D$14=1,G31-0.5,G31) | H32: =IF('Inputs'!$D$14=1,H31-0.5,H31) | I32: =IF('Inputs'!$D$14=1,I31-0.5,I31) | J32: =IF('Inputs'!$D$14=1,J31-0.5,J31) | K32: =IF('Inputs'!$D$14=1,K31-0.5,K31)
B33: Discount factor | G33: =1/(1+$D$21)^G32 | H33: =1/(1+$D$21)^H32 | I33: =1/(1+$D$21)^I32 | J33: =1/(1+$D$21)^J32 | K33: =1/(1+$D$21)^K32
B34: PV of unlevered FCF | G34: =G30*G33 | H34: =H30*H33 | I34: =I30*I33 | J34: =J30*J33 | K34: =K30*K33
B36: Terminal value & valuation | D36: Gordon Growth | E36: Exit Multiple
B37: Sum of PV of free cash flows | D37: =SUM(G34:K34) | E37: =SUM(G34:K34)
B38: Terminal growth rate / exit multiple | D38: ='Inputs'!$D$12 | E38: ='Inputs'!$D$13
B39: Final-year FCF / EBITDA (FY2020) | D39: =K30 | E39: ='IS'!K17
B40: Terminal value | D40: =D39*(1+D38)/($D$21-D38) | E40: =E39*E38
B41: Terminal discount factor (end of final year) | D41: =1/(1+$D$21)^K31 | E41: =1/(1+$D$21)^K31
B42: PV of terminal value | D42: =D40*D41 | E42: =E40*E41
B43: Enterprise value | D43: =D37+D42 | E43: =E37+E42
...

Sheet LBO
B1: Apple Inc.: Leveraged Buyout Analysis
B2: USD in millions, except per-share data. Blue = input / reported, black = formula, green = link to another sheet.
F3: Close | G3: Holding period
B4: Fiscal year ending September | F4: 2015 | G4: 2016 | H4: 2017 | I4: 2018 | J4: 2019 | K4: 2020
B6: Entry valuation
B7: LTM EBITDA (FY2015) | D7: ='IS'!F17
B8: Entry EV / EBITDA | D8: ='Inputs'!$D$50
B9: Entry enterprise value | D9: =$D$7*$D$8
B10: Less: existing debt | D10: ='BS'!F44
B11: Plus: cash & marketable securities | D11: ='BS'!F45
B12: Equity purchase price | D12: =$D$9-$D$10+$D$11
B13: Diluted shares (m) | D13: ='Inputs'!$D$23
B14: Implied offer price per share | D14: =$D$12/$D$13
B15: Premium to current share price | D15: =$D$14/'Inputs'!$D$7-1
B17: Cash available at close
B18: Offshore cash & securities | D18: ='Inputs'!$D$24
B19: Domestic cash & securities | D19: =$D$11-$D$18
B20: Minimum operating cash | D20: ='Inputs'!$D$55
B21: Domestic cash used to fund the deal | D21: =MAX($D$19-$D$20,0)
B22: Cash retained on balance sheet | D22: =$D$19-$D$21
B23: Offshore cash repatriated | D23: =$D$18*'Inputs'!$D$58
B24: Repatriation tax paid | D24: =$D$23*'Inputs'!$D$16
B25: Offshore cash remaining trapped | D25: =$D$18-$D$23
B27: Uses of funds
B28: Purchase of equity | D28: =$D$12
B29: Refinance existing debt | D29: =$D$10
B30: Advisory & transaction fees | D30: =$D$9*'Inputs'!$D$56
B31: Financing fees | D31: =$D$35*'Inputs'!$D$57
B32: Total uses | D32: =SUM(D28:D31)
B34: Sources of funds
B35: Total new debt | D35: =$D$9*'Inputs'!$D$53
B36: Senior Term Loan B | D36: =$D$35*'Inputs'!$D$63
B37: Senior Subordinated Notes | D37: =$D$35*'Inputs'!$D$69
B38: Existing cash & securities used | D38: =$D$21+$D$23-$D$24
B39: Sponsor equity | D39: =$D$32-$D$35-$D$38
B40: Total sources | D40: =SUM(D36:D39)
B41: Check: sources - uses | D41: =$D$40-$D$32
B42: Total debt / LTM EBITDA | D42: =$D$35/$D$7
B44: Cash flow available for debt service
B45: EBITDA | G45: ='IS'!G17 | H45: ='IS'!H17 | I45: ='IS'!I17 | J45: ='IS'!J17 | K45: ='IS'!K17
...

Sheet Sensitivity
B1: Apple Inc.: Sensitivity Analysis
B2: Heat maps: green = higher value. Base case outlined in bold.
B4: Grid steps (inputs)
B5: WACC step | D5: 0.005
B6: Terminal growth step | D6: 0.005
B7: Exit multiple step | D7: 1
B9: DCF (Gordon Growth): implied share price
B10: Live formulas: each cell reprices the full DCF from the FCF row on the DCF sheet.
C11: WACC ↓ / Terminal growth → | D11: ='Inputs'!$D$12+(-2)*$D$6 | E11: ='Inputs'!$D$12+(-1)*$D$6 | F11: ='Inputs'!$D$12+(0)*$D$6 | G11: ='Inputs'!$D$12+(1)*$D$6 | H11: ='Inputs'!$D$12+(2)*$D$6
C12: ='DCF'!$D$21+(-2)*$D$5 | D12: =(SUMPRODUCT('DCF'!$G$30:$K$30,(1+$C12)^(-'DCF'!$G$32:$K$32))+'DCF'!$K$30*(1+D$11)/($C12-D$11)/(1+$C12)^'DCF'!$K$31+'DCF'!$D$44+'DCF'!$D$45+'DCF'!$D$46)/'DCF'!$D$48 | E12: =(SUMPRODUCT('DCF'!$G$30:$K$30,(1+$C12)^(-'DCF'!$G$32:$K$32))+'DCF'!$K$30*(1+E$11)/($C12-E$11)/(1+$C12)^'DCF'!$K$31+'DCF'!$D$44+'DCF'!$D$45+'DCF'!$D$46)/'DCF'!$D$48 | F12: =(SUMPRODUCT('DCF'!$G$30:$K$30,(1+$C12)^(-'DCF'!$G$32:$K$32))+'DCF'!$K$30*(1+F$11)/($C12-F$11)/(1+$C12)^'DCF'!$K$31+'DCF'!$D$44+'DCF'!$D$45+'DCF'!$D$46)/'DCF'!$D$48 | G12: =(SUMPRODUCT('DCF'!$G$30:$K$30,(1+$C12)^(-'DCF'!$G$32:$K$32))+'DCF'!$K$30*(1+G$11)/($C12-G$11)/(1+$C12)^'DCF'!$K$31+'DCF'!$D$44+'DCF'!$D$45+'DCF'!$D$46)/'DCF'!$D$48 | H12: =(SUMPRODUCT('DCF'!$G$30:$K$30,(1+$C12)^(-'DCF'!$G$32:$K$32))+'DCF'!$K$30*(1+H$11)/($C12-H$11)/(1+$C12)^'DCF'!$K$31+'DCF'!$D$44+'DCF'!$D$45+'DCF'!$D$46)/'DCF'!$D$48
C13: ='DCF'!$D$21+(-1)*$D$5 | D13: =(SUMPRODUCT('DCF'!$G$30:$K$30,(1+$C13)^(-'DCF'!$G$32:$K$32))+'DCF'!$K$30*(1+D$11)/($C13-D$11)/(1+$C13)^'DCF'!$K$31+'DCF'!$D$44+'DCF'!$D$45+'DCF'!$D$46)/'DCF'!$D$48 | E13: =(SUMPRODUCT('DCF'!$G$30:$K$30,(1+$C13)^(-'DCF'!$G$32:$K$32))+'DCF'!$K$30*(1+E$11)/($C13-E$11)/(1+$C13)^'DCF'!$K$31+'DCF'!$D$44+'DCF'!$D$45+'DCF'!$D$46)/'DCF'!$D$48 | F13: =(SUMPRODUCT('DCF'!$G$30:$K$30,(1+$C13)^(-'DCF'!$G$32:$K$32))+'DCF'!$K$30*(1+F$11)/($C13-F$11)/(1+$C13)^'DCF'!$K$31+'DCF'!$D$44+'DCF'!$D$45+'DCF'!$D$46)/'DCF'!$D$48 | G13: =(SUMPRODUCT('DCF'!$G$30:$K$30,(1+$C13)^(-'DCF'!$G$32:$K$32))+'DCF'!$K$30*(1+G$11)/($C13-G$11)/(1+$C13)^'DCF'!$K$31+'DCF'!$D$44+'DCF'!$D$45+'DCF'!$D$46)/'DCF'!$D$48 | H13: =(SUMPRODUCT('DCF'!$G$30:$K$30,(1+$C13)^(-'DCF'!$G$32:$K$32))+'DCF'!$K$30*(1+H$11)/($C13-H$11)/(1+$C13)^'DCF'!$K$31+'DCF'!$D$44+'DCF'!$D$45+'DCF'!$D$46)/'DCF'!$D$48
C14: ='DCF'!$D$21+(0)*$D$5 | D14: =(SUMPRODUCT('DCF'!$G$30:$K$30,(1+$C14)^(-'DCF'!$G$32:$K$32))+'DCF'!$K$30*(1+D$11)/($C14-D$11)/(1+$C14)^'DCF'!$K$31+'DCF'!$D$44+'DCF'!$D$45+'DCF'!$D$46)/'DCF'!$D$48 | E14: =(SUMPRODUCT('DCF'!$G$30:$K$30,(1+$C14)^(-'DCF'!$G$32:$K$32))+'DCF'!$K$30*(1+E$11)/($C14-E$11)/(1+$C14)^'DCF'!$K$31+'DCF'!$D$44+'DCF'!$D$45+'DCF'!$D$46)/'DCF'!$D$48 | F14: =(SUMPRODUCT('DCF'!$G$30:$K$30,(1+$C14)^(-'DCF'!$G$32:$K$32))+'DCF'!$K$30*(1+F$11)/($C14-F$11)/(1+$C14)^'DCF'!$K$31+'DCF'!$D$44+'DCF'!$D$45+'DCF'!$D$46)/'DCF'!$D$48 | G14: =(SUMPRODUCT('DCF'!$G$30:$K$30,(1+$C14)^(-'DCF'!$G$32:$K$32))+'DCF'!$K$30*(1+G$11)/($C14-G$11)/(1+$C14)^'DCF'!$K$31+'DCF'!$D$44+'DCF'!$D$45+'DCF'!$D$46)/'DCF'!$D$48 | H14: =(SUMPRODUCT('DCF'!$G$30:$K$30,(1+$C14)^(-'DCF'!$G$32:$K$32))+'DCF'!$K$30*(1+H$11)/($C14-H$11)/(1+$C14)^'DCF'!$K$31+'DCF'!$D$44+'DCF'!$D$45+'DCF'!$D$46)/'DCF'!$D$48
C15: ='DCF'!$D$21+(1)*$D$5 | D15: =(SUMPRODUCT('DCF'!$G$30:$K$30,(1+$C15)^(-'DCF'!$G$32:$K$32))+'DCF'!$K$30*(1+D$11)/($C15-D$11)/(1+$C15)^'DCF'!$K$31+'DCF'!$D$44+'DCF'!$D$45+'DCF'!$D$46)/'DCF'!$D$48 | E15: =(SUMPRODUCT('DCF'!$G$30:$K$30,(1+$C15)^(-'DCF'!$G$32:$K$32))+'DCF'!$K$30*(1+E$11)/($C15-E$11)/(1+$C15)^'DCF'!$K$31+'DCF'!$D$44+'DCF'!$D$45+'DCF'!$D$46)/'DCF'!$D$48 | F15: =(SUMPRODUCT('DCF'!$G$30:$K$30,(1+$C15)^(-'DCF'!$G$32:$K$32))+'DCF'!$K$30*(1+F$11)/($C15-F$11)/(1+$C15)^'DCF'!$K$31+'DCF'!$D$44+'DCF'!$D$45+'DCF'!$D$46)/'DCF'!$D$48 | G15: =(SUMPRODUCT('DCF'!$G$30:$K$30,(1+$C15)^(-'DCF'!$G$32:$K$32))+'DCF'!$K$30*(1+G$11)/($C15-G$11)/(1+$C15)^'DCF'!$K$31+'DCF'!$D$44+'DCF'!$D$45+'DCF'!$D$46)/'DCF'!$D$48 | H15: =(SUMPRODUCT('DCF'!$G$30:$K$30,(1+$C15)^(-'DCF'!$G$32:$K$32))+'DCF'!$K$30*(1+H$11)/($C15-H$11)/(1+$C15)^'DCF'!$K$31+'DCF'!$D$44+'DCF'!$D$45+'DCF'!$D$46)/'DCF'!$D$48
C16: ='DCF'!$D$21+(2)*$D$5 | D16: =(SUMPRODUCT('DCF'!$G$30:$K$30,(1+$C16)^(-'DCF'!$G$32:$K$32))+'DCF'!$K$30*(1+D$11)/($C16-D$11)/(1+$C16)^'DCF'!$K$31+'DCF'!$D$44+'DCF'!$D$45+'DCF'!$D$46)/'DCF'!$D$48 | E16: =(SUMPRODUCT('DCF'!$G$30:$K$30,(1+$C16)^(-'DCF'!$G$32:$K$32))+'DCF'!$K$30*(1+E$11)/($C16-E$11)/(1+$C16)^'DCF'!$K$31+'DCF'!$D$44+'DCF'!$D$45+'DCF'!$D$46)/'DCF'!$D$48 | F16: =(SUMPRODUCT('DCF'!$G$30:$K$30,(1+$C16)^(-'DCF'!$G$32:$K$32))+'DCF'!$K$30*(1+F$11)/($C16-F$11)/(1+$C16)^'DCF'!$K$31+'DCF'!$D$44+'DCF'!$D$45+'DCF'!$D$46)/'DCF'!$D$48 | G16: =(SUMPRODUCT('DCF'!$G$30:$K$30,(1+$C16)^(-'DCF'!$G$32:$K$32))+'DCF'!$K$30*(1+G$11)/($C16-G$11)/(1+$C16)^'DCF'!$K$31+'DCF'!$D$44+'DCF'!$D$45+'DCF'!$D$46)/'DCF'!$D$48 | H16: =(SUMPRODUCT('DCF'!$G$30:$K$30,(1+$C16)^(-'DCF'!$G$32:$K$32))+'DCF'!$K$30*(1+H$11)/($C16-H$11)/(1+$C16)^'DCF'!$K$31+'DCF'!$D$44+'DCF'!$D$45+'DCF'!$D$46)/'DCF'!$D$48
B18: DCF (Exit Multiple): implied share price
B19: Live formulas: terminal value = final-year EBITDA x exit multiple.
C20: Exit EV/EBITDA ↓ / WACC → | D20: ='DCF'!$D$21+(-2)*$D$5 | E20: ='DCF'!$D$21+(-1)*$D$5 | F20: ='DCF'!$D$21+(0)*$D$5 | G20: ='DCF'!$D$21+(1)*$D$5 | H20: ='DCF'!$D$21+(2)*$D$5
C21: ='Inputs'!$D$13+(-2)*$D$7 | D21: =(SUMPRODUCT('DCF'!$G$30:$K$30,(1+D$20)^(-'DCF'!$G$32:$K$32))+'IS'!$K$17*$C21/(1+D$20)^'DCF'!$K$31+'DCF'!$D$44+'DCF'!$D$45+'DCF'!$D$46)/'DCF'!$D$48 | E21: =(SUMPRODUCT('DCF'!$G$30:$K$30,(1+E$20)^(-'DCF'!$G$32:$K$32))+'IS'!$K$17*$C21/(1+E$20)^'DCF'!$K$31+'DCF'!$D$44+'DCF'!$D$45+'DCF'!$D$46)/'DCF'!$D$48 | F21: =(SUMPRODUCT('DCF'!$G$30:$K$30,(1+F$20)^(-'DCF'!$G$32:$K$32))+'IS'!$K$17*$C21/(1+F$20)^'DCF'!$K$31+'DCF'!$D$44+'DCF'!$D$45+'DCF'!$D$46)/'DCF'!$D$48 | G21: =(SUMPRODUCT('DCF'!$G$30:$K$30,(1+G$20)^(-'DCF'!$G$32:$K$32))+'IS'!$K$17*$C21/(1+G$20)^'DCF'!$K$31+'DCF'!$D$44+'DCF'!$D$45+'DCF'!$D$46)/'DCF'!$D$48 | H21: =(SUMPRODUCT('DCF'!$G$30:$K$30,(1+H$20)^(-'DCF'!$G$32:$K$32))+'IS'!$K$17*$C21/(1+H$20)^'DCF'!$K$31+'DCF'!$D$44+'DCF'!$D$45+'DCF'!$D$46)/'DCF'!$D$48
C22: ='Inputs'!$D$13+(-1)*$D$7 | D22: =(SUMPRODUCT('DCF'!$G$30:$K$30,(1+D$20)^(-'DCF'!$G$32:$K$32))+'IS'!$K$17*$C22/(1+D$20)^'DCF'!$K$31+'DCF'!$D$44+'DCF'!$D$45+'DCF'!$D$46)/'DCF'!$D$48 | E22: =(SUMPRODUCT('DCF'!$G$30:$K$30,(1+E$20)^(-'DCF'!$G$32:$K$32))+'IS'!$K$17*$C22/(1+E$20)^'DCF'!$K$31+'DCF'!$D$44+'DCF'!$D$45+'DCF'!$D$46)/'DCF'!$D$48 | F22: =(SUMPRODUCT('DCF'!$G$30:$K$30,(1+F$20)^(-'DCF'!$G$32:$K$32))+'IS'!$K$17*$C22/(1+F$20)^'DCF'!$K$31+'DCF'!$D$44+'DCF'!$D$45+'DCF'!$D$46)/'DCF'!$D$48 | G22: =(SUMPRODUCT('DCF'!$G$30:$K$30,(1+G$20)^(-'DCF'!$G$32:$K$32))+'IS'!$K$17*$C22/(1+G$20)^'DCF'!$K$31+'DCF'!$D$44+'DCF'!$D$45+'DCF'!$D$46)/'DCF'!$D$48 | H22: =(SUMPRODUCT('DCF'!$G$30:$K$30,(1+H$20)^(-'DCF'!$G$32:$K$32))+'IS'!$K$17*$C22/(1+H$20)^'DCF'!$K$31+'DCF'!$D$44+'DCF'!$D$45+'DCF'!$D$46)/'DCF'!$D$48
C23: ='Inputs'!$D$13+(0)*$D$7 | D23: =(SUMPRODUCT('DCF'!$G$30:$K$30,(1+D$20)^(-'DCF'!$G$32:$K$32))+'IS'!$K$17*$C23/(1+D$20)^'DCF'!$K$31+'DCF'!$D$44+'DCF'!$D$45+'DCF'!$D$46)/'DCF'!$D$48 | E23: =(SUMPRODUCT('DCF'!$G$30:$K$30,(1+E$20)^(-'DCF'!$G$32:$K$32))+'IS'!$K$17*$C23/(1+E$20)^'DCF'!$K$31+'DCF'!$D$44+'DCF'!$D$45+'DCF'!$D$46)/'DCF'!$D$48 | F23: =(SUMPRODUCT('DCF'!$G$30:$K$30,(1+F$20)^(-'DCF'!$G$32:$K$32))+'IS'!$K$17*$C23/(1+F$20)^'DCF'!$K$31+'DCF'!$D$44+'DCF'!$D$45+'DCF'!$D$46)/'DCF'!$D$48 | G23: =(SUMPRODUCT('DCF'!$G$30:$K$30,(1+G$20)^(-'DCF'!$G$32:$K$32))+'IS'!$K$17*$C23/(1+G$20)^'DCF'!$K$31+'DCF'!$D$44+'DCF'!$D$45+'DCF'!$D$46)/'DCF'!$D$48 | H23: =(SUMPRODUCT('DCF'!$G$30:$K$30,(1+H$20)^(-'DCF'!$G$32:$K$32))+'IS'!$K$17*$C23/(1+H$20)^'DCF'!$K$31+'DCF'!$D$44+'DCF'!$D$45+'DCF'!$D$46)/'DCF'!$D$48
C24: ='Inputs'!$D$13+(1)*$D$7 | D24: =(SUMPRODUCT('DCF'!$G$30:$K$30,(1+D$20)^(-'DCF'!$G$32:$K$32))+'IS'!$K$17*$C24/(1+D$20)^'DCF'!$K$31+'DCF'!$D$44+'DCF'!$D$45+'DCF'!$D$46)/'DCF'!$D$48 | E24: =(SUMPRODUCT('DCF'!$G$30:$K$30,(1+E$20)^(-'DCF'!$G$32:$K$32))+'IS'!$K$17*$C24/(1+E$20)^'DCF'!$K$31+'DCF'!$D$44+'DCF'!$D$45+'DCF'!$D$46)/'DCF'!$D$48 | F24: =(SUMPRODUCT('DCF'!$G$30:$K$30,(1+F$20)^(-'DCF'!$G$32:$K$32))+'IS'!$K$17*$C24/(1+F$20)^'DCF'!$K$31+'DCF'!$D$44+'DCF'!$D$45+'DCF'!$D$46)/'DCF'!$D$48 | G24: =(SUMPRODUCT('DCF'!$G$30:$K$30,(1+G$20)^(-'DCF'!$G$32:$K$32))+'IS'!$K$17*$C24/(1+G$20)^'DCF'!$K$31+'DCF'!$D$44+'DCF'!$D$45+'DCF'!$D$46)/'DCF'!$D$48 | H24: =(SUMPRODUCT('DCF'!$G$30:$K$30,(1+H$20)^(-'DCF'!$G$32:$K$32))+'IS'!$K$17*$C24/(1+H$20)^'DCF'!$K$31+'DCF'!$D$44+'DCF'!$D$45+'DCF'!$D$46)/'DCF'!$D$48
C25: ='Inputs'!$D$13+(2)*$D$7 | D25: =(SUMPRODUCT('DCF'!$G$30:$K$30,(1+D$20)^(-'DCF'!$G$32:$K$32))+'IS'!$K$17*$C25/(1+D$20)^'DCF'!$K$31+'DCF'!$D$44+'DCF'!$D$45+'DCF'!$D$46)/'DCF'!$D$48 | E25: =(SUMPRODUCT('DCF'!$G$30:$K$30,(1+E$20)^(-'DCF'!$G$32:$K$32))+'IS'!$K$17*$C25/(1+E$20)^'DCF'!$K$31+'DCF'!$D$44+'DCF'!$D$45+'DCF'!$D$46)/'DCF'!$D$48 | F25: =(SUMPRODUCT('DCF'!$G$30:$K$30,(1+F$20)^(-'DCF'!$G$32:$K$32))+'IS'!$K$17*$C25/(1+F$20)^'DCF'!$K$31+'DCF'!$D$44+'DCF'!$D$45+'DCF'!$D$46)/'DCF'!$D$48 | G25: =(SUMPRODUCT('DCF'!$G$30:$K$30,(1+G$20)^(-'DCF'!$G$32:$K$32))+'IS'!$K$17*$C25/(1+G$20)^'DCF'!$K$31+'DCF'!$D$44+'DCF'!$D$45+'DCF'!$D$46)/'DCF'!$D$48 | H25: =(SUMPRODUCT('DCF'!$G$30:$K$30,(1+H$20)^(-'DCF'!$G$32:$K$32))+'IS'!$K$17*$C25/(1+H$20)^'DCF'!$K$31+'DCF'!$D$44+'DCF'!$D$45+'DCF'!$D$46)/'DCF'!$D$48
B27: LBO sponsor IRR (exit fixed at 8.0x)
B28: Engine values: each cell re-runs the full debt waterfall (path-dependent, so not expressible as a single-cell formula).
C29: Entry EV/EBITDA ↓ / Debt % of entry EV → | D29: 0.3 | E29: 0.4 | F29: 0.5 | G29: 0.6 | H29: 0.7
C30: 6 | D30: 0.12672824 | E30: 0.13342391 | F30: 0.14080115 | G30: 0.14985864 | H30: 0.16105824
C31: 7 | D31: 0.097262711 | E31: 0.1016717 | F31: 0.10685404 | G31: 0.11338993 | H31: 0.12163051
C32: 8 | D32: 0.07035923 | E32: 0.072185999 | F32: 0.074748035 | G32: 0.07797224 | H32: 0.082153957
C33: 9 | D33: 0.045290882 | E33: 0.044618243 | F33: 0.043968026 | G33: 0.04312998 | H33: 0.042008964
C34: 10 | D34: 0.021926985 | E34: 0.018472972 | F34: 0.01413737 | G34: 0.0084028372 | H34: 0.00045822298
B36: LBO sponsor MOIC (exit fixed at 8.0x)
B37: Engine values: each cell re-runs the full debt waterfall (path-dependent, so not expressible as a single-cell formula).
C38: Entry EV/EBITDA ↓ / Debt % of entry EV → | D38: 0.3 | E38: 0.4 | F38: 0.5 | G38: 0.6 | H38: 0.7
C39: 6 | D39: 1.8159166 | E39: 1.8705178 | F39: 1.9321897 | G39: 2.0101213 | H39: 2.1099396
C40: 7 | D40: 1.5905712 | E40: 1.6227849 | F40: 1.6613142 | G40: 1.7109465 | H40: 1.7752072
C41: 8 | D41: 1.4049077 | E41: 1.4169374 | F41: 1.4339477 | G41: 1.4555861 | H41: 1.4840388
C42: 9 | D42: 1.2479173 | E42: 1.2439073 | F42: 1.2400408 | G42: 1.2350716 | H42: 1.2284494
C43: 10 | D43: 1.1145494 | E43: 1.095841 | F43: 1.072714 | G43: 1.0427262 | H43: 1.0022932

Sheet Scenarios
B1: Apple Inc.: Scenario Analysis
B2: Engine values: each scenario re-runs the full projection, DCF and LBO with the overrides in config/scenarios.json.
B4: Key assumptions
C5: Base | D5: Bull | E5: Bear | F5: Bull vs Base | G5: Bear vs Base
B6: Average revenue growth | C6: 0.035 | D6: 0.062 | E6: -0.016
B7: Average gross margin | C7: 0.396 | D7: 0.405 | E7: 0.378
B8: LBO exit EV / EBITDA | C8: 8 | D8: 9.5 | E8: 6.5
B9: DCF terminal EV / EBITDA | C9: 10 | D9: 10 | E9: 8
B10: Offshore cash repatriated at close | C10: 0 | D10: 1 | E10: 0
B11: Repatriation tax rate | C11: 0.32786885 | D11: 0.14 | E11: 0.32786885
B13: Outputs and variance vs. base
C14: Base | D14: Bull | E14: Bear | F14: Bull vs Base | G14: Bear vs Base
B15: Revenue CAGR | C15: 0.034990338 | D15: 0.061973591 | E15: -0.01659745 | F15: 0.026983253 | G15: -0.051587788
B16: Final-year revenue | C16: 277567.15 | D16: 315685.89 | E16: 214952.86 | F16: 38118.742 | G16: -62614.284
B17: Final-year EBITDA | C17: 93262.562 | D17: 110805.75 | E17: 68999.87 | F17: 17543.186 | G17: -24262.692
B18: Final-year EBITDA margin | C18: 0.336 | D18: 0.351 | E18: 0.321 | F18: 0.015 | G18: -0.015
B19: Cumulative unlevered FCF | C19: 281473.93 | D19: 318855.76 | E19: 210903.15 | F19: 37381.832 | G19: -70570.779
B20: DCF price: Gordon Growth | C20: 206.91898 | D20: 248.77052 | E20: 154.64991 | F20: 41.851536 | G20: -52.26907
B21: DCF price: Exit Multiple | C21: 171.57473 | D21: 204.89447 | E21: 114.0559 | F21: 33.319738 | G21: -57.518823
B22: Sponsor equity | C22: 540045.92 | D22: 379311.92 | E22: 540045.92 | F22: -160734 | G22: 0
B23: Exit equity | C23: 774397.58 | D23: 994881.23 | E23: 400975.2 | F23: 220483.65 | G23: -373422.38
B24: Sponsor MOIC | C24: 1.4339477 | D24: 2.6228578 | E24: 0.74248352 | F24: 1.1889102 | G24: -0.69146413
B25: Sponsor IRR | C25: 0.074748035 | D25: 0.21270439 | E25: -0.057812443 | F25: 0.13795635 | G25: -0.13256048
B26: Peak Debt / EBITDA | C26: 3.4960984 | D26: 3.3159862 | E26: 4.2293211 | F26: -0.18011223 | G26: 0.73322273
... B29: Acquisition debt repaid by exit | C29: 0.67472381 | D29: 0.79459378 | E29: 0.44492688 | F29: 0.11986997 | G29: -0.22979693
B31: Recommendation: PASS
B32: Base-case IRR 7.5% vs. 20% hurdle | C32: Not met
B33: Base-case MOIC 1.43x vs. 2.0x minimum | C33: Not met
B34: Base-case maintenance covenants met in every year (minimum EBITDA cushion 26%) | C34: Met

Sheet Checks
B1: Apple Inc.: Model Integrity Checks
B2: Every check must be zero (within $0.5M). Flag 1 = error.
B4: MASTER CHECK | C4: =IF(SUM(D6:D31)=0,"OK","ERROR")
B5: Check | C5: Difference | D5: Flag
B6: IS: Check: segments - net sales FY2013 | C6: ='IS'!D36 | D6: =IF(ABS(C6)<0.5,0,1)
B7: IS: Check: segments - net sales FY2014 | C7: ='IS'!E36 | D7: =IF(ABS(C7)<0.5,0,1)
B8: IS: Check: segments - net sales FY2015 | C8: ='IS'!F36 | D8: =IF(ABS(C8)<0.5,0,1)
B9: IS: Check: segments - net sales FY2013 | C9: ='IS'!D45 | D9: =IF(ABS(C9)<0.5,0,1)
B10: IS: Check: segments - net sales FY2014 | C10: ='IS'!E45 | D10: =IF(ABS(C10)<0.5,0,1)
B11: IS: Check: segments - net sales FY2015 | C11: ='IS'!F45 | D11: =IF(ABS(C11)<0.5,0,1)
B12: BS: Check: Assets - (Liabilities + Equity) FY2014 | C12: ='BS'!E40 | D12: =IF(ABS(C12)<0.5,0,1)
B13: BS: Check: Assets - (Liabilities + Equity) FY2015 | C13: ='BS'!F40 | D13: =IF(ABS(C13)<0.5,0,1)
B14: BS: Check: Assets - (Liabilities + Equity) FY2016 | C14: ='BS'!G40 | D14: =IF(ABS(C14)<0.5,0,1)
B15: BS: Check: Assets - (Liabilities + Equity) FY2017 | C15: ='BS'!H40 | D15: =IF(ABS(C15)<0.5,0,1)
B16: BS: Check: Assets - (Liabilities + Equity) FY2018 | C16: ='BS'!I40 | D16: =IF(ABS(C16)<0.5,0,1)
B17: BS: Check: Assets - (Liabilities + Equity) FY2019 | C17: ='BS'!J40 | D17: =IF(ABS(C17)<0.5,0,1)
B18: BS: Check: Assets - (Liabilities + Equity) FY2020 | C18: ='BS'!K40 | D18: =IF(ABS(C18)<0.5,0,1)
B19: CFS: Check: ending cash - balance sheet cash FY2014 | C19: ='CFS'!E47 | D19: =IF(ABS(C19)<0.5,0,1)
B20: CFS: Check: ending cash - balance sheet cash FY2015 | C20: ='CFS'!F47 | D20: =IF(ABS(C20)<0.5,0,1)
B21: CFS: Check: ending cash - balance sheet cash FY2016 | C21: ='CFS'!G47 | D21: =IF(ABS(C21)<0.5,0,1)
B22: CFS: Check: ending cash - balance sheet cash FY2017 | C22: ='CFS'!H47 | D22: =IF(ABS(C22)<0.5,0,1)
B23: CFS: Check: ending cash - balance sheet cash FY2018 | C23: ='CFS'!I47 | D23: =IF(ABS(C23)<0.5,0,1)
B24: CFS: Check: ending cash - balance sheet cash FY2019 | C24: ='CFS'!J47 | D24: =IF(ABS(C24)<0.5,0,1)
B25: CFS: Check: ending cash - balance sheet cash FY2020 | C25: ='CFS'!K47 | D25: =IF(ABS(C25)<0.5,0,1)
B26: CFS: Check: CFS net income - IS net income FY2013 | C26: ='CFS'!D48 | D26: =IF(ABS(C26)<0.5,0,1)
B27: CFS: Check: CFS net income - IS net income FY2014 | C27: ='CFS'!E48 | D27: =IF(ABS(C27)<0.5,0,1)
B28: CFS: Check: CFS net income - IS net income FY2015 | C28: ='CFS'!F48 | D28: =IF(ABS(C28)<0.5,0,1)
B29: Debt: Check: tranches - reported total | C29: ='Debt'!D39 | D29: =IF(ABS(C29)<0.5,0,1)
B30: Debt: Check: carrying value - balance sheet | C30: ='Debt'!D44 | D30: =IF(ABS(C30)<0.5,0,1)
B31: LBO: Check: sources - uses | C31: ='LBO'!D41 | D31: =IF(ABS(C31)<0.5,0,1)
